### Post 349
**Post URL**: /t/tds-official-project1-discrepencies/171141/349
- **ID**: 616156
- **Author**: NK (23f2004042)
- **Created At**: 2025-04-06T15:10:52.149Z
- **Content**:  
  <a class="mention" href="/u/carlton">@carlton</a> and <a class="mention" href="/u/jivraj">@Jivraj</a> , for Task A i had tested before and all the test cases passed, but all my A tasks has failed with 0, In the evaluation logs, i could see that all task A tests failed due to datagen.py not available.
Could you rerun the test ?
- **Reactions**: None
- **Post Number**: 349

