### Post 87
**Post URL**: /t/ga3-large-language-models-discussion-thread-tds-jan-2025/163247/87
- **ID**: 590682
- **Author**: Jayaram (22f3002723)
- **Created At**: 2025-02-04T18:07:26.462Z
- **Content**:  
  For question 1 getting the below response … not sure what it means<br>
ythonError: Traceback (most recent call last): File “/lib/python312.zip/_pyodide/_base.py”, line 523, in eval_code .run(globals, locals) ^^^^^^^^^^^^^^^^^^^^ File “/lib/python312.zip/_pyodide/_base.py”, line 357, in run coroutine = eval(self.code, globals, locals) ^^^^^^^^^^^^^^^^^^^^^^^^^^^^^^^^ File “”, line 53, in  TypeError: unhashable type: ‘dict’
- **Reactions**: None
- **Post Number**: 87

